Workbook
Name H0_1_p: Data!$AC$2
Name LF0_1_p: Data!$AA$2
Name N0_1_p: Data!$AB$2
Name N0_p: Data!$AL$2
Name P0_D_1_p: Data!$Y$2
Name P0_MR_1_p: Data!$X$2
Name phiM_F_1_1_p: Data!$H$2
Name phiM_F_2_1_p: Data!$H$3
Name phiM_F_3_1_p: Data!$H$4
Name phiM_F_4_1_p: Data!$H$5
Name phiM_F_5_1_p: Data!$H$6
Name phiM_I_1_1_p: Data!$G$2
Name phiM_I_2_1_p: Data!$G$3
Name phiM_I_3_1_p: Data!$G$4
Name phiM_I_4_1_p: Data!$G$5
Name phiM_I_5_1_p: Data!$G$6
Name phiM_p: Data!$AL$4
Name phiN0_1_1_p: Data!$C$2
Name phiN0_2_1_p: Data!$C$3
Name phiN0_3_1_p: Data!$C$4
Name phiN0_4_1_p: Data!$C$5
Name phiN0_5_1_p: Data!$C$6
Name phiQ_D_1_1_1_p: Data!$U$2
Name phiQ_D_2_1_1_p: Data!$U$3
Name phiQ_D_3_1_1_p: Data!$U$4
Name phiQ_D_4_1_1_p: Data!$U$5
Name phiQ_D_5_1_1_p: Data!$U$6
Name phiQI_1_1_1_p: Data!$O$2
Name phiQI_1_1_2_p: Data!$O$3
Name phiQI_1_1_3_p: Data!$O$4
Name phiQI_1_1_4_p: Data!$O$5
Name phiQI_1_1_p: Data!$I$2
Name phiQI_2_1_1_p: Data!$O$6
Name phiQI_2_1_2_p: Data!$O$7
Name phiQI_2_1_3_p: Data!$O$8
Name phiQI_2_1_4_p: Data!$O$9
Name phiQI_2_1_p: Data!$I$3
Name phiQI_3_1_1_p: Data!$O$10
Name phiQI_3_1_2_p: Data!$O$11
Name phiQI_3_1_3_p: Data!$O$12
Name phiQI_3_1_4_p: Data!$O$13
Name phiQI_3_1_p: Data!$I$4
Name phiQI_4_1_1_p: Data!$O$14
Name phiQI_4_1_2_p: Data!$O$15
Name phiQI_4_1_3_p: Data!$O$16
Name phiQI_4_1_4_p: Data!$O$17
Name phiQI_4_1_p: Data!$I$5
Name phiQI_5_1_1_p: Data!$O$18
Name phiQI_5_1_2_p: Data!$O$19
Name phiQI_5_1_3_p: Data!$O$20
Name phiQI_5_1_4_p: Data!$O$21
Name phiQI_5_1_p: Data!$I$6
Name phiW_1_1_p: Data!$E$2
Name phiW_2_1_p: Data!$E$3
Name phiW_3_1_p: Data!$E$4
Name phiW_4_1_p: Data!$E$5
Name phiW_5_1_p: Data!$E$6
Name phiX_1_1_p: Data!$F$2
Name phiX_2_1_p: Data!$F$3
Name phiX_3_1_p: Data!$F$4

Sheet Content
A1: Sheets
A2: =HYPERLINK("#'Data'!A1","Data") -> Data | B2: a sheet to store data used for calibration
A3: =HYPERLINK("#'Start'!A1","Start") -> Start | B3: a sheet to assign values for the initial conditions
A4: =HYPERLINK("#'Structural Parameters'!A1","Structural Parameters") -> Structural Parameters | B4: a sheet to assign values for structural parameters
A5: =HYPERLINK("#'Baseline'!A1","Baseline") -> Baseline | B5: a sheet for the baseline scenario
A6: =HYPERLINK("#'Scenario'!A1","Scenario") -> Scenario | B6: a sheet for a specific scenario you want to run
A7: Regions
A8: 1 | B8: VNM
A9: Sectors
A10: 1 | B10: Primary
A11: 2 | B11: Fossil
A12: 3 | B12: Renewables
A13: 4 | B13: Secondary
A14: 5 | B14: Tertiary

Sheet Data
A1: Sector | B1: Region | C1: Initial Employment (phiN0) | D1: Initial Value Added (phiY0) | E1: Labour Cost (phiW) | F1: Exports (phiX) | G1: Import Intermediate (phiM_I) | H1: Import final (phiM_F) | I1: Intermediate (phiQI) | J1: emission share (sE) | L1: Subsector | M1: Region | N1: Sector of Origin | O1: intermediate input share (phiQI) | P1: share of emissions (sEI) | R1: Subsector | S1: Region of Origin | T1: Region of Destination | U1: demand of products from different regions (phiQ_D) | W1: Region | X1: initial price level imports (P0_MR) | Y1: initial domestic price level (P0_D) | Z1: initial population (PoP0) | AA1: initial labour force (LF0) | AB1: initial employment (N0) | AC1: initial stocks of houses (H0) | AE1: Region | AF1: initial surface temperature (Celsius) (tas0) | AH1: Name | AI1: Value | AK1: Name | AL1: Value
A2: Primary | B2: VNM | C2: =[1]Data!C2 -> 0 | D2: =[1]Data!D2 -> 0 | E2: =[1]Data!E2 -> 0 | F2: =[1]Data!F2 -> 0 | G2: =[1]Data!G2 -> 0 | H2: =[1]Data!H2 -> 0 | I2: =[1]Data!I2 -> 0 | J2: =[1]Data!J2 -> 0 | L2: Primary | M2: VNM | N2: Primary | O2: =[1]Data!O2 -> 0 | P2: 0 | R2: Primary | S2: VNM | T2: VNM | U2: 1 | W2: VNM | X2: enter value here | Y2: enter value here | Z2: enter value here | AA2: enter value here | AB2: enter value here | AC2: enter value here | AE2: VNM | AF2: enter value here | AH2: initial Sea level | AI2: enter value here | AK2: initial employment | AL2: 0.25
A3: Fossil | B3: VNM | C3: =SUM([1]Data!C3:C4) -> 0 | D3: =SUM([1]Data!D3:D4) -> 0 | E3: =SUM([1]Data!E3:E4) -> 0 | F3: =SUM([1]Data!F3:F4) -> 0 | G3: =SUM([1]Data!G3:G4) -> 0 | H3: =SUM([1]Data!H3:H4) -> 0 | I3: =SUM([1]Data!I3:I4) -> 0 | J3: =SUM([1]Data!J3:J4) -> 0 | L3: Primary | M3: VNM | N3: Energy | O3: =SUM([1]Data!O3:O5) -> 0 | P3: 0 | R3: Fossil | S3: VNM | T3: VNM | U3: 1 | AK3: initial value added | AL3: 5
A4: Renewables | B4: VNM | C4: =[1]Data!C5 -> 0 | D4: =[1]Data!D5 -> 0 | E4: =[1]Data!E5 -> 0 | F4: =[1]Data!F5 -> 0 | G4: =[1]Data!G5 -> 0 | H4: =[1]Data!H5 -> 0 | I4: =[1]Data!I5 -> 0 | J4: =[1]Data!J5 -> 0 | L4: Primary | M4: VNM | N4: Secondary | O4: =[1]Data!O6 -> 0 | P4: 0 | R4: Renewables | S4: VNM | T4: VNM | U4: 1 | AK4: import share | AL4: 0.2
A5: Secondary | B5: VNM | C5: =[1]Data!C6 -> 0 | D5: =[1]Data!D6 -> 0 | E5: =[1]Data!E6 -> 0 | F5: =[1]Data!F6 -> 0 | G5: =[1]Data!G6 -> 0 | H5: =[1]Data!H6 -> 0 | I5: =[1]Data!I6 -> 0 | J5: =[1]Data!J6 -> 0 | L5: Primary | M5: VNM | N5: Tertiary | O5: =[1]Data!O7 -> 0 | P5: 0 | R5: Secondary | S5: VNM | T5: VNM | U5: 1 | AK5: investmetns in residential building relative to GDP | AL5: 0.001
A6: Tertiary | B6: VNM | C6: =[1]Data!C7 -> 0 | D6: =[1]Data!D7 -> 0 | E6: =[1]Data!E7 -> 0 | F6: =[1]Data!F7 -> 0 | G6: =[1]Data!G7 -> 0 | H6: =[1]Data!H7 -> 0 | I6: =[1]Data!I7 -> 0 | J6: =[1]Data!J7 -> 0 | L6: Fossil | M6: VNM | N6: Primary | O6: {=([1]Data!O8*[1]!phiQI_2_1_p+ [1]!phiQI_3_1_p*[1]Data!O14)/([1]!phiQI_2_1_p+ [1]!phiQI_3_1_p)} -> #DIV/0! | P6: 0 | R6: Tertiary | S6: VNM | T6: VNM | U6: 1 | AK6: tax on labour | AL6: 0
L7: Fossil | M7: VNM | N7: Energy | O7: {=(SUM([1]Data!O9:O11)*[1]!phiQI_2_1_p+ [1]!phiQI_3_1_p*SUM([1]Data!O15:O17))/([1]!phiQI_2_1_p+ [1]!phiQI_3_1_p)} -> #DIV/0! | P7: 0 | AK7: tax on capital income | AL7: 0
L8: Fossil | M8: VNM | N8: Secondary | O8: {=([1]Data!O12*[1]!phiQI_2_1_p+ [1]!phiQI_3_1_p*[1]Data!O18)/([1]!phiQI_2_1_p+ [1]!phiQI_3_1_p)} -> #DIV/0! | P8: 0 | AK8: tax on consumption | AL8: 0.2
L9: Fossil | M9: VNM | N9: Tertiary | O9: {=([1]Data!O13*[1]!phiQI_2_1_p+ [1]!phiQI_3_1_p*[1]Data!O19)/([1]!phiQI_2_1_p+ [1]!phiQI_3_1_p)} -> #DIV/0! | P9: 0
L10: Renewables | M10: VNM | N10: Primary | O10: =([1]Data!O20) -> 4.9975012e-05 | P10: 0
L11: Renewables | M11: VNM | N11: Energy | O11: =SUM([1]Data!O21:O23) -> 0.42333833 | P11: 0
L12: Renewables | M12: VNM | N12: Secondary | O12: =[1]Data!O24 -> 0.45564718 | P12: 0
L13: Renewables | M13: VNM | N13: Tertiary | O13: =[1]Data!O25 -> 0.12096452 | P13: 0
L14: Secondary | M14: VNM | N14: Primary | O14: =[1]Data!O26 -> 0.1229528 | P14: 0
L15: Secondary | M15: VNM | N15: Energy | O15: =SUM([1]Data!O27:O29) -> 0.043097412 | P15: 0
L16: Secondary | M16: VNM | N16: Secondary | O16: =[1]Data!O30 -> 0.69489614 | P16: 0
L17: Secondary | M17: VNM | N17: Tertiary | O17: =[1]Data!O31 -> 0.13905364 | P17: 0
L18: Tertiary | M18: VNM | N18: Primary | O18: =[1]Data!O32 -> 0.028366958 | P18: 0
L19: Tertiary | M19: VNM | N19: Energy | O19: =SUM([1]Data!O33:O35) -> 0.029715291 | P19: 0
L20: Tertiary | M20: VNM | N20: Secondary | O20: =[1]Data!O36 -> 0.5135883 | P20: 0
L21: Tertiary | M21: VNM | N21: Tertiary | O21: =[1]Data!O37 -> 0.42832945 | P21: 0

Sheet Start
A1: Parameter | B1: Value | C1: Description
A2: Y0_p | B2: 5 | C2: initial GDP
A3: Parameter values for initial sum of hours worked to potential hours worked
A4: N0_1_p | B4: =15/100 -> 0.15 | C4: initial sum of hours worked to potential hours worked in region 1
A5: Parameter values for initial emission price
A6: P0_1_p | B6: =0/100 -> 0 | C6: initial emission price in region 1
A7: Parameter values for initial emissionss
A8: E0_1_p | B8: 1 | C8: initial emissionss in region 1
A9: PE0_1_p | B9: 0.01 | C9: initial price for emissions
A10: Parameter values for investmetns in residential building relative to GDP
A11: sH_1_p | B11: =1/100 -> 0.01 | C11: investmetns in residential building relative to GDP in region 1
A12: Parameter values for initial population
A13: PoP0_1_p | B13: 1 | C13: initial population in region 1
A14: Parameter values for initial labour force
A15: LF0_1_p | B15: =0.96*B13 -> 0.96 | C15: initial labour force in region 1
A16: Parameter values for initial housing
A17: H0_1_p | B17: =25 -> 25 | C17: initial housing in region 1
A18: Parameter values for initial value for tas
A19: tas0_1_p | B19: =0 -> 0 | C19: initial value for tas in region 1
A20: SL0_p | B20: =0 -> 0 | C20: initial value for SL
A21: Parameter values for initial share of value added
A22: phiY0_1_1_p | B22: 0.042502925 | C22: initial share of value added in sector 1 and region 1 | D22: =B22/(B22+'Structural Parameters'!B29) -> 0.35132008
A23: phiY0_2_1_p | B23: 0.02 | C23: initial share of value added in sector 2 and region 1 | D23: =B23/(B23+'Structural Parameters'!B30) -> 0.38369102
A24: phiY0_3_1_p | B24: 0.005 | C24: initial share of value added in sector 3 and region 1 | D24: =B24/(B24+'Structural Parameters'!B31) -> 0.33333333
A25: phiY0_4_1_p | B25: 0.11652957 | C25: initial share of value added in sector 4 and region 1 | D25: =B25/(B25+'Structural Parameters'!B32) -> 0.19124757
A26: phiY0_5_1_p | B26: 0.095695592 | C26: initial share of value added in sector 5 and region 1 | D26: =B26/(B26+'Structural Parameters'!B33) -> 0.45477878
A27: Parameter values for initial share of employment
A28: phiN0_1_1_p | B28: 0.43502823 | C28: initial share of employment in sector 1 and region 1
A29: phiN0_2_1_p | B29: 0.0061 | C29: initial share of employment in sector 2 and region 1
A30: phiN0_3_1_p | B30: 0.0009 | C30: initial share of employment in sector 3 and region 1
A31: phiN0_4_1_p | B31: 0.22463843 | C31: initial share of employment in sector 4 and region 1
A32: phiN0_5_1_p | B32: 0.33333334 | C32: initial share of employment in sector 5 and region 1

Sheet Structural Parameters
A1: Parameter | B1: Value | C1: Description
A2: beta_p | B2: 0.97 | C2: discount factor
A3: delta_p | B3: =45/1000 -> 0.045 | C3: depreciation rate
A4: deltaB_p | B4: =45/1000 -> 0.045 | C4: depreciation rate
A5: phiB_p | B5: 1 | C5: foreign bond adjustment cost
A6: phiadjB_p | B6: 0.1 | C6: foreign bond adjustment cost
A7: phiK_p | B7: 40 | C7: investment adjustment cost
A8: sigmaL_p | B8: =5/10 -> 0.5 | C8: inverse Frisch elasticity
A9: sigmaC_p | B9: =1 -> 1 | C9: intertemporal elasticity of substitution for consumption
A10: etaQ_p | B10: 0.6 | C10: elasticity of substitution between sectors
A11: etaF_p | B11: 0.6 | C11: elasticity of substitution between imports and domestic products
A12: etaX_p | B12: 0.6 | C12: supply price elasticity of exports
A13: tauC_p | B13: 0.2 | C13: consumption tax rate
A14: tauNH_p | B14: 0 | C14: tax rate on labour income
A15: tauKH_p | B15: 0 | C15: tax rate on capital income
A16: Parameter values for elasticity of substitution between subsectors in one sector
A17: etaQA_1_p | B17: 1 | C17: elasticity of substitution between subsectors in one sector in sector 1
A18: etaQA_2_p | B18: 5 | C18: elasticity of substitution between subsectors in one sector in sector 2
A19: etaQA_3_p | B19: 1 | C19: elasticity of substitution between subsectors in one sector in sector 3
A20: etaQA_4_p | B20: 1 | C20: elasticity of substitution between subsectors in one sector in sector 4
A21: etaQA_5_p | B21: 1 | C21: elasticity of substitution between subsectors in one sector in sector 5
A22: Parameter values for elasticity of substitution between regions in one subsector
A23: etaQ_1_p | B23: 2 | C23: elasticity of substitution between regions in one subsector in sector 1
A24: etaQ_2_p | B24: 2 | C24: elasticity of substitution between regions in one subsector in sector 2
A25: etaQ_3_p | B25: 2 | C25: elasticity of substitution between regions in one subsector in sector 3
A26: etaQ_4_p | B26: 2 | C26: elasticity of substitution between regions in one subsector in sector 4
A27: etaQ_5_p | B27: 2 | C27: elasticity of substitution between regions in one subsector in sector 5
A28: Parameter values for cost share of intermediate goods
A29: phiQI_1_1_p | B29: 0.078477706 | C29: cost share of intermediate goods in sector 1 and region 1
A30: phiQI_2_1_p | B30: 0.032125276 | C30: cost share of intermediate goods in sector 2 and region 1
A31: phiQI_3_1_p | B31: 0.01 | C31: cost share of intermediate goods in sector 3 and region 1
A32: phiQI_4_1_p | B32: 0.4927831 | C32: cost share of intermediate goods in sector 4 and region 1
A33: phiQI_5_1_p | B33: 0.1147267 | C33: cost share of intermediate goods in sector 5 and region 1
A34: Parameter values for final use import shares
A35: phiM_F_1_1_p | B35: 0.0025539137 | C35: final use import shares in sector 1 and region 1
A36: phiM_F_2_1_p | B36: 0.0018043361 | C36: final use import shares in sector 2 and region 1
A37: phiM_F_3_1_p | B37: 0.00031841225 | C37: final use import shares in sector 3 and region 1
A38: phiM_F_4_1_p | B38: 0.029708519 | C38: final use import shares in sector 4 and region 1
A39: phiM_F_5_1_p | B39: 0.016244187 | C39: final use import shares in sector 5 and region 1
A40: Parameter values for intermediate import shares
...

Sheet Baseline
A1: Time | B1: exo_LF_1 | C1: exo_NLF_1 | D1: exo_NX_1 | E1: exo_B_1 | F1: exo_NXL_1 | G1: exo_BL_1 | H1: gY_1_1 | I1: gN_1_1 | J1: gY_2_1 | K1: gN_2_1 | L1: gY_3_1 | M1: gN_3_1 | N1: gY_4_1 | O1: gN_4_1 | P1: gY_5_1 | Q1: gN_5_1 | R1: exo_E_2_1 | S1: E_2_1 | T1: Y | U1: gY | V1: N_1_1 | W1: N_2_1 | X1: N_3_1 | Y1: N_4_1 | Z1: N_5_1 | AA1: N | AB1: exo_PE_1 | AC1: exo_Q_2_1 | AD1: phiY_1_1 | AE1: phiY_2_1 | AF1: phiY_3_1 | AG1: phiY_4_1 | AH1: phiY_5_1
A2: 2 | B2: 0 | C2: 0 | D2: 0 | E2: 0 | F2: 0 | G2: 0 | H2: =AD3/AD2*U2 -> 0.99 | I2: 0.99 | J2: =AE3/AE2*U2 -> 1.0175 | K2: 1 | L2: =AF3/AF2*U2 -> 1.122 | M2: 1 | N2: =AG3/AG2*U2 -> 1.089 | O2: =N2 -> 1.089 | P2: =AH3/AH2*U2 -> 1.1783437 | Q2: 1 | R2: =LN(S2) -> 0.048790164 | S2: 1.05 | T2: 1.1 | U2: =T2 -> 1.1 | V2: =Start!$B28*Start!$B$4 -> 0.065254234 | W2: =Start!$B29*Start!$B$4 -> 0.000915 | X2: =Start!$B30*Start!$B$4 -> 0.000135 | Y2: =Start!$B31*Start!$B$4 -> 0.033695765 | Z2: =Start!$B32*Start!$B$4 -> 0.050000001 | AA2: =SUM(V2:Z2) -> 0.15 | AB2: =(0.002+0.00025*A2)*T2*5/S2 -> 0.013095238 | AC2: =R2*0.5 -> 0.024395082 | AD2: =Start!B22/SUM(Start!$B$22:$B$26) -> 0.15194372 | AE2: =Start!B23/SUM(Start!$B$22:$B$26) -> 0.071498006 | AF2: =Start!B24/SUM(Start!$B$22:$B$26) -> 0.017874501 | AG2: =Start!B25/SUM(Start!$B$22:$B$26) -> 0.41658158 | AH2: =Start!B26/SUM(Start!$B$22:$B$26) -> 0.3421022
A3: 3 | B3: 0.013280752 | C3: 0.0021978191 | D3: 0 | E3: 0 | F3: 0 | G3: 0 | H3: =AD4/AD3*U3 -> 0.99 | I3: =V3/V2 -> 0.9 | J3: =AE4/AE3*U3 -> 1.0175 | K3: 1 | L3: =AF4/AF3*U3 -> 1.122 | M3: =(X3/X2) -> 1.122 | N3: =AG4/AG3*U3 -> 1.089 | O3: =(Y3/Y2) -> 0.99 | P3: =AH4/AH3*U3 -> 1.1672204 | Q3: =Z3/Z2 -> 1.1369182 | R3: =LN(S3) -> 0.088010877 | S3: =MAX(0.5,S2*(1.05-0.01*($A3-$A$2))) -> 1.092 | T3: =T2*1.1 -> 1.21 | U3: =T3/T2 -> 1.1 | V3: =MAX(0.001,V2*0.9) -> 0.05872881 | W3: =W2 -> 0.000915 | X3: =L3*X2 -> 0.00015147 | Y3: =N3/U3*Y2 -> 0.033358807 | Z3: =AA3-SUM(V3:Y3) -> 0.056845913 | AA3: =AA2 -> 0.15 | AB3: =(0.002+0.00025*A3)*T3*5/S3 -> 0.015235806 | AC3: =R3*0.5 -> 0.044005439 | AD3: =MAX(0.01,AD2*0.9) -> 0.13674935 | AE3: =MAX(0.005,AE2*0.925) -> 0.066135655 | AF3: =MIN(0.05,AF2*1.02) -> 0.018231991 | AG3: =MAX(0.3,AG2*0.99) -> 0.41241576 | AH3: =1-SUM(AD3:AG3) -> 0.36646724
A4: 4 | B4: 0.026327978 | C4: 0.0044313875 | D4: 0 | E4: 0 | F4: 0 | G4: 0 | H4: =AD5/AD4*U4 -> 0.99 | I4: =V4/V3 -> 0.9 | J4: =AE5/AE4*U4 -> 1.0175 | K4: 1 | L4: =AF5/AF4*U4 -> 1.122 | M4: =(X4/X3) -> 1.122 | N4: =AG5/AG4*U4 -> 1.089 | O4: =(Y4/Y3) -> 0.99 | P4: =AH5/AH4*U4 -> 1.1582912 | Q4: =Z4/Z3 -> 1.1088555 | R4: =LN(S4) -> 0.11756968 | S4: =MAX(0.5,S3*(1.05-0.01*($A4-$A$2))) -> 1.12476 | T4: =T3*1.1 -> 1.331 | U4: =T4/T3 -> 1.1 | V4: =MAX(0.001,V3*0.9) -> 0.052855929 | W4: =W3 -> 0.000915 | X4: =L4*X3 -> 0.00016994934 | Y4: =N4/U4*Y3 -> 0.033025219 | Z4: =AA4-SUM(V4:Y4) -> 0.063033902 | AA4: =AA3 -> 0.15 | AB4: =(0.002+0.00025*A4)*T4*5/S4 -> 0.017750453 | AC4: =R4*0.5 -> 0.05878484 | AD4: =MAX(0.01,AD3*0.9) -> 0.12307441 | AE4: =MAX(0.005,AE3*0.925) -> 0.061175481 | AF4: =MIN(0.05,AF3*1.02) -> 0.018596631 | AG4: =MAX(0.3,AG3*0.99) -> 0.40829161 | AH4: =1-SUM(AD4:AG4) -> 0.38886187
A5: 5 | B5: 0.039030698 | C5: 0.0065627985 | D5: 0 | E5: 0 | F5: 0 | G5: 0 | H5: =AD6/AD5*U5 -> 0.99 | I5: =V5/V4 -> 0.9 | J5: =AE6/AE5*U5 -> 1.0175 | K5: 1 | L5: =AF6/AF5*U5 -> 1.122 | M5: =(X5/X4) -> 1.122 | N5: =AG6/AG5*U5 -> 1.089 | O5: =(Y5/Y4) -> 0.99 | P5: =AH6/AH5*U5 -> 1.1509974 | Q5: =Z5/Z4 -> 1.0887635 | R5: =LN(S5) -> 0.13737231 | S5: =MAX(0.5,S4*(1.05-0.01*($A5-$A$2))) -> 1.1472552 | T5: =T4*1.1 -> 1.4641 | U5: =T5/T4 -> 1.1 | V5: =MAX(0.001,V4*0.9) -> 0.047570336 | W5: =W4 -> 0.000915 | X5: =L5*X4 -> 0.00019068316 | Y5: =N5/U5*Y4 -> 0.032694967 | Z5: =AA5-SUM(V5:Y5) -> 0.068629014 | AA5: =AA4 -> 0.15 | AB5: =(0.002+0.00025*A5)*T5*5/S5 -> 0.020737866 | AC5: =R5*0.5 -> 0.068686153 | AD5: =MAX(0.01,AD4*0.9) -> 0.11076697 | AE5: =MAX(0.005,AE4*0.925) -> 0.05658732 | AF5: =MIN(0.05,AF4*1.02) -> 0.018968564 | AG5: =MAX(0.3,AG4*0.99) -> 0.40420869 | AH5: =1-SUM(AD5:AG5) -> 0.40946846
A6: 6 | B6: 0.051256342 | C6: 0.0084316845 | D6: 0 | E6: 0 | F6: 0 | G6: 0 | H6: =AD7/AD6*U6 -> 0.99 | I6: =V6/V5 -> 0.9 | J6: =AE7/AE6*U6 -> 1.0175 | K6: 1 | L6: =AF7/AF6*U6 -> 1.122 | M6: =(X6/X5) -> 1.122 | N6: =AG7/AG6*U6 -> 1.089 | O6: =(Y6/Y5) -> 0.99 | P6: =AH7/AH6*U6 -> 1.1449535 | Q6: =Z6/Z5 -> 1.0737402 | R6: =LN(S6) -> 0.14732264 | S6: =MAX(0.5,S5*(1.05-0.01*($A6-$A$2))) -> 1.1587278 | T6: =T5*1.1 -> 1.61051 | U6: =T6/T5 -> 1.1 | V6: =MAX(0.001,V5*0.9) -> 0.042813303 | W6: =W5 -> 0.000915 | X6: =L6*X5 -> 0.0002139465 | Y6: =N6/U6*Y5 -> 0.032368017 | Z6: =AA6-SUM(V6:Y6) -> 0.073689734 | AA6: =AA5 -> 0.15 | AB6: =(0.002+0.00025*A6)*T6*5/S6 -> 0.024323164 | AC6: =R6*0.5 -> 0.073661319 | AD6: =MAX(0.01,AD5*0.9) -> 0.099690273 | AE6: =MAX(0.005,AE5*0.925) -> 0.052343271 | AF6: =MIN(0.05,AF5*1.02) -> 0.019347935 | AG6: =MAX(0.3,AG5*0.99) -> 0.4001666 | AH6: =1-SUM(AD6:AG6) -> 0.42845192
A7: 7 | B7: 0.062916135 | C7: 0.0099206127 | D7: 0 | E7: 0 | F7: 0 | G7: 0 | H7: =AD8/AD7*U7 -> 0.9675 | I7: =V7/V6 -> 0.9 | J7: =AE8/AE7*U7 -> 0.994375 | K7: 1 | L7: =AF8/AF7*U7 -> 1.0965 | M7: =(X7/X6) -> 1.0965 | N7: =AG8/AG7*U7 -> 1.06425 | O7: =(Y7/Y6) -> 0.99 | P7: =AH8/AH7*U7 -> 1.1139791 | Q7: =Z7/Z6 -> 1.0622117 | R7: =LN(S7) -> 0.14732264 | S7: =MAX(0.5,S6*(1.05-0.01*($A7-$A$2))) -> 1.1587278 | T7: =T6*1.075 -> 1.7312983 | U7: =T7/T6 -> 1.075 | V7: =MAX(0.001,V6*0.9) -> 0.038531973 | W7: =W6 -> 0.000915 | X7: =L7*X6 -> 0.00023459234 | Y7: =N7/U7*Y6 -> 0.032044337 | Z7: =AA7-SUM(V7:Y7) -> 0.078274098 | AA7: =AA6 -> 0.15 | AB7: =(0.002+0.00025*A7)*T7*5/S7 -> 0.028015073 | AC7: =R7*0.5 -> 0.073661319 | AD7: =MAX(0.01,AD6*0.9) -> 0.089721246 | AE7: =MAX(0.005,AE6*0.925) -> 0.048417526 | AF7: =MIN(0.05,AF6*1.02) -> 0.019734894 | AG7: =MAX(0.3,AG6*0.99) -> 0.39616494 | AH7: =1-SUM(AD7:AG7) -> 0.4459614
A8: 8 | B8: 0.073956933 | C8: 0.010977036 | D8: 0 | E8: 0 | F8: 0 | G8: 0 | H8: =AD9/AD8*U8 -> 0.9675 | I8: =V8/V7 -> 0.9 | J8: =AE9/AE8*U8 -> 0.994375 | K8: 1 | L8: =AF9/AF8*U8 -> 1.0965 | M8: =(X8/X7) -> 1.0965 | N8: =AG9/AG8*U8 -> 1.06425 | O8: =(Y8/Y7) -> 0.99 | P8: =AH9/AH8*U8 -> 1.1097841 | Q8: =Z8/Z7 -> 1.0530316 | R8: =LN(S8) -> 0.1372723 | S8: =MAX(0.5,S7*(1.05-0.01*($A8-$A$2))) -> 1.1471405 | T8: =T7*1.075 -> 1.8611456 | U8: =T8/T7 -> 1.075 | V8: =MAX(0.001,V7*0.9) -> 0.034678775 | W8: =W7 -> 0.000915 | X8: =L8*X7 -> 0.0002572305 | Y8: =N8/U8*Y7 -> 0.031723894 | Z8: =AA8-SUM(V8:Y8) -> 0.082425101 | AA8: =AA7 -> 0.15 | AB8: =(0.002+0.00025*A8)*T8*5/S8 -> 0.032448434 | AC8: =R8*0.5 -> 0.068636151 | AD8: =MAX(0.01,AD7*0.9) -> 0.080749121 | AE8: =MAX(0.005,AE7*0.925) -> 0.044786211 | AF8: =MIN(0.05,AF7*1.02) -> 0.020129592 | AG8: =MAX(0.3,AG7*0.99) -> 0.39220329 | AH8: =1-SUM(AD8:AG8) -> 0.46213179
A9: 9 | B9: 0.082436154 | C9: 0.0097791301 | D9: 0 | E9: 0 | F9: 0 | G9: 0 | H9: =AD10/AD9*U9 -> 0.9675 | I9: =V9/V8 -> 0.9 | J9: =AE10/AE9*U9 -> 0.994375 | K9: 1 | L9: =AF10/AF9*U9 -> 1.0965 | M9: =(X9/X8) -> 1.0965 | N9: =AG10/AG9*U9 -> 1.06425 | O9: =(Y9/Y8) -> 0.99 | P9: =AH10/AH9*U9 -> 1.1062002 | Q9: =Z9/Z8 -> 1.0456207 | R9: =LN(S9) -> 0.11706959 | S9: =MAX(0.5,S8*(1.05-0.01*($A9-$A$2))) -> 1.1241977 | T9: =T8*1.075 -> 2.0007315 | U9: =T9/T8 -> 1.075 | V9: =MAX(0.001,V8*0.9) -> 0.031210898 | W9: =W8 -> 0.000915 | X9: =L9*X8 -> 0.00028205325 | Y9: =N9/U9*Y8 -> 0.031406655 | Z9: =AA9-SUM(V9:Y9) -> 0.086185394 | AA9: =AA8 -> 0.15 | AB9: =(0.002+0.00025*A9)*T9*5/S9 -> 0.037818567 | AC9: =R9*0.5 -> 0.058534797 | AD9: =MAX(0.01,AD8*0.9) -> 0.072674209 | AE9: =MAX(0.005,AE8*0.925) -> 0.041427245 | AF9: =MIN(0.05,AF8*1.02) -> 0.020532184 | AG9: =MAX(0.3,AG8*0.99) -> 0.38828125 | AH9: =1-SUM(AD9:AG9) -> 0.47708511
A10: 10 | B10: 0.090746583 | C10: 0.008871351 | D10: 0 | E10: 0 | F10: 0 | G10: 0 | H10: =AD11/AD10*U10 -> 0.9675 | I10: =V10/V9 -> 0.9 | J10: =AE11/AE10*U10 -> 0.994375 | K10: 1 | L10: =AF11/AF10*U10 -> 1.0965 | M10: =(X10/X9) -> 1.0965 | N10: =AG11/AG10*U10 -> 1.06425 | O10: =(Y10/Y9) -> 0.99 | P10: =AH11/AH10*U10 -> 1.1031155 | Q10: =Z10/Z9 -> 1.0395419 | R10: =LN(S10) -> 0.086610387 | S10: =MAX(0.5,S9*(1.05-0.01*($A10-$A$2))) -> 1.0904717 | T10: =T9*1.075 -> 2.1507864 | U10: =T10/T9 -> 1.075 | V10: =MAX(0.001,V9*0.9) -> 0.028089808 | W10: =W9 -> 0.000915 | X10: =L10*X9 -> 0.00030927139 | Y10: =N10/U10*Y9 -> 0.031092588 | Z10: =AA10-SUM(V10:Y10) -> 0.089593333 | AA10: =AA9 -> 0.15 | AB10: =(0.002+0.00025*A10)*T10*5/S10 -> 0.044377761 | AC10: =R10*0.5 -> 0.043305194 | AD10: =MAX(0.01,AD9*0.9) -> 0.065406788 | AE10: =MAX(0.005,AE9*0.925) -> 0.038320202 | AF10: =MIN(0.05,AF9*1.02) -> 0.020942827 | AG10: =MAX(0.3,AG9*0.99) -> 0.38439844 | AH10: =1-SUM(AD10:AG10) -> 0.49093174
A11: 11 | B11: 0.098853018 | C11: 0.0083714865 | D11: 0 | E11: 0 | F11: 0 | G11: 0 | H11: =AD12/AD11*U11 -> 0.9675 | I11: =V11/V10 -> 0.9 | J11: =AE12/AE11*U11 -> 0.994375 | K11: 1 | L11: =AF12/AF11*U11 -> 1.0965 | M11: =(X11/X10) -> 1.0965 | N11: =AG12/AG11*U11 -> 1.06425 | O11: =(Y11/Y10) -> 0.99 | P11: =AH12/AH11*U11 -> 1.1004434 | Q11: =Z11/Z10 -> 1.0344899 | R11: =LN(S11) -> 0.045788393 | S11: =MAX(0.5,S10*(1.05-0.01*($A11-$A$2))) -> 1.0468529 | T11: =T10*1.075 -> 2.3120954 | U11: =T11/T10 -> 1.075 | V11: =MAX(0.001,V10*0.9) -> 0.025280827 | W11: =W10 -> 0.000915 | X11: =L11*X10 -> 0.00033911607 | Y11: =N11/U11*Y10 -> 0.030781662 | Z11: =AA11-SUM(V11:Y11) -> 0.092683395 | AA11: =AA10 -> 0.15 | AB11: =(0.002+0.00025*A11)*T11*5/S11 -> 0.052454616 | AC11: =R11*0.5 -> 0.022894196 | AD11: =MAX(0.01,AD10*0.9) -> 0.058866109 | AE11: =MAX(0.005,AE10*0.925) -> 0.035446187 | AF11: =MIN(0.05,AF10*1.02) -> 0.021361684 | AG11: =MAX(0.3,AG10*0.99) -> 0.38055446 | AH11: =1-SUM(AD11:AG11) -> 0.50377156
A12: 12 | B12: 0.10672064 | C12: 0.0083992858 | D12: 0 | E12: 0 | F12: 0 | G12: 0 | H12: =AD13/AD12*U12 -> 0.9675 | I12: =V12/V11 -> 0.9 | J12: =AE13/AE12*U12 -> 0.994375 | K12: 1 | L12: =AF13/AF12*U12 -> 1.0965 | M12: =(X12/X11) -> 1.0965 | N12: =AG13/AG12*U12 -> 1.06425 | O12: =(Y12/Y11) -> 0.99 | P12: =AH13/AH12*U12 -> 1.0981152 | Q12: =Z12/Z11 -> 1.0302446 | R12: =LN(S12) -> -0.0055049018 | S12: =MAX(0.5,S11*(1.05-0.01*($A12-$A$2))) -> 0.99451022 | T12: =T11*1.075 -> 2.4855025 | U12: =T12/T11 -> 1.075 | V12: =MAX(0.001,V11*0.9) -> 0.022752744 | W12: =W11 -> 0.000915 | X12: =L12*X11 -> 0.00037184078 | Y12: =N12/U12*Y11 -> 0.030473846 | Z12: =AA12-SUM(V12:Y12) -> 0.095486569 | AA12: =AA11 -> 0.15 | AB12: =(0.002+0.00025*A12)*T12*5/S12 -> 0.062480568 | AC12: =R12*0.5 -> -0.0027524509 | AD12: =MAX(0.01,AD11*0.9) -> 0.052979498 | AE12: =MAX(0.005,AE11*0.925) -> 0.032787723 | AF12: =MIN(0.05,AF11*1.02) -> 0.021788917 | AG12: =MAX(0.3,AG11*0.99) -> 0.37674891 | AH12: =1-SUM(AD12:AG12) -> 0.51569495
A13: 13 | B13: 0.11212457 | C13: 0.0069098571 | D13: 0 | E13: 0 | F13: 0 | G13: 0 | H13: =AD14/AD13*U13 -> 0.9675 | I13: =V13/V12 -> 0.9 | J13: =AE14/AE13*U13 -> 0.994375 | K13: 1 | L13: =AF14/AF13*U13 -> 1.0965 | M13: =(X13/X12) -> 1.0965 | N13: =AG14/AG13*U13 -> 1.06425 | O13: =(Y13/Y12) -> 0.99 | P13: =AH14/AH13*U13 -> 1.0960765 | Q13: =Z13/Z12 -> 1.0266439 | R13: =LN(S13) -> -0.067380306 | S13: =MAX(0.5,S12*(1.05-0.01*($A13-$A$2))) -> 0.93483961 | T13: =T12*1.075 -> 2.6719152 | U13: =T13/T12 -> 1.075 | V13: =MAX(0.001,V12*0.9) -> 0.02047747 | W13: =W12 -> 0.000915 | X13: =L13*X12 -> 0.00040772341 | Y13: =N13/U13*Y12 -> 0.030169107 | Z13: =AA13-SUM(V13:Y13) -> 0.098030699 | AA13: =AA12 -> 0.15 | AB13: =(0.002+0.00025*A13)*T13*5/S13 -> 0.075026533 | AC13: =R13*0.5 -> -0.033690153 | AD13: =MAX(0.01,AD12*0.9) -> 0.047681549 | AE13: =MAX(0.005,AE12*0.925) -> 0.030328644 | AF13: =MIN(0.05,AF12*1.02) -> 0.022224696 | AG13: =MAX(0.3,AG12*0.99) -> 0.37298142 | AH13: =1-SUM(AD13:AG13) -> 0.52678369
A14: 14 | B14: 0.11720618 | C14: 0.006321377 | D14: 0 | E14: 0 | F14: 0 | G14: 0 | H14: =AD15/AD14*U14 -> 0.9675 | I14: =V14/V13 -> 0.9 | J14: =AE15/AE14*U14 -> 0.994375 | K14: 1 | L14: =AF15/AF14*U14 -> 1.0965 | M14: =(X14/X13) -> 1.0965 | N14: =AG15/AG14*U14 -> 1.06425 | O14: =(Y14/Y13) -> 0.99 | P14: =AH15/AH14*U14 -> 1.094283 | Q14: =Z14/Z13 -> 1.023565 | R14: =LN(S14) -> -0.139951 | S14: =MAX(0.5,S13*(1.05-0.01*($A14-$A$2))) -> 0.86940084 | T14: =T13*1.075 -> 2.8723089 | U14: =T14/T13 -> 1.075 | V14: =MAX(0.001,V13*0.9) -> 0.018429723 | W14: =W13 -> 0.000915 | X14: =L14*X13 -> 0.00044706872 | Y14: =N14/U14*Y13 -> 0.029867416 | Z14: =AA14-SUM(V14:Y14) -> 0.10034079 | AA14: =AA13 -> 0.15 | AB14: =(0.002+0.00025*A14)*T14*5/S14 -> 0.090853943 | AC14: =R14*0.5 -> -0.069975499 | AD14: =MAX(0.01,AD13*0.9) -> 0.042913394 | AE14: =MAX(0.005,AE13*0.925) -> 0.028053995 | AF14: =MIN(0.05,AF13*1.02) -> 0.02266919 | AG14: =MAX(0.3,AG13*0.99) -> 0.36925161 | AH14: =1-SUM(AD14:AG14) -> 0.53711181
A15: 15 | B15: 0.12189565 | C15: 0.006865972 | D15: 0 | E15: 0 | F15: 0 | G15: 0 | H15: =AD16/AD15*U15 -> 0.9675 | I15: =V15/V14 -> 0.9 | J15: =AE16/AE15*U15 -> 0.994375 | K15: 1 | L15: =AF16/AF15*U15 -> 1.0965 | M15: =(X15/X14) -> 1.0965 | N15: =AG16/AG15*U15 -> 1.06425 | O15: =(Y15/Y14) -> 0.99 | P15: =AH16/AH15*U15 -> 1.0926987 | Q15: =Z15/Z14 -> 1.0209138 | R15: =LN(S15) -> -0.22333261 | S15: =MAX(0.5,S14*(1.05-0.01*($A15-$A$2))) -> 0.79984877 | T15: =T14*1.075 -> 3.087732 | U15: =T15/T14 -> 1.075 | V15: =MAX(0.001,V14*0.9) -> 0.016586751 | W15: =W14 -> 0.000915 | X15: =L15*X14 -> 0.00049021085 | Y15: =N15/U15*Y14 -> 0.029568742 | Z15: =AA15-SUM(V15:Y15) -> 0.1024393 | AA15: =AA14 -> 0.15 | AB15: =(0.002+0.00025*A15)*T15*5/S15 -> 0.11098635 | AC15: =R15*0.5 -> -0.1116663 | AD15: =MAX(0.01,AD14*0.9) -> 0.038622054 | AE15: =MAX(0.005,AE14*0.925) -> 0.025949946 | AF15: =MIN(0.05,AF14*1.02) -> 0.023122574 | AG15: =MAX(0.3,AG14*0.99) -> 0.36555909 | AH15: =1-SUM(AD15:AG15) -> 0.54674633
A16: 16 | B16: 0.12612296 | C16: 0.0087754084 | D16: 0 | E16: 0 | F16: 0 | G16: 0 | H16: =AD17/AD16*U16 -> 0.9675 | I16: =V16/V15 -> 0.9 | J16: =AE17/AE16*U16 -> 0.994375 | K16: 1 | L16: =AF17/AF16*U16 -> 1.0965 | M16: =(X16/X15) -> 1.0965 | N16: =AG17/AG16*U16 -> 1.06425 | O16: =(Y16/Y15) -> 0.99 | P16: =AH17/AH16*U16 -> 1.091294 | Q16: =Z16/Z15 -> 1.0186165 | R16: =LN(S16) -> -0.31764329 | S16: =MAX(0.5,S15*(1.05-0.01*($A16-$A$2))) -> 0.72786238 | T16: =T15*1.075 -> 3.3193119 | U16: =T16/T15 -> 1.075 | V16: =MAX(0.001,V15*0.9) -> 0.014928076 | W16: =W15 -> 0.000915 | X16: =L16*X15 -> 0.0005375162 | Y16: =N16/U16*Y15 -> 0.029273055 | Z16: =AA16-SUM(V16:Y16) -> 0.10434635 | AA16: =AA15 -> 0.15 | AB16: =(0.002+0.00025*A16)*T16*5/S16 -> 0.1368107 | AC16: =R16*0.5 -> -0.15882164 | AD16: =MAX(0.01,AD15*0.9) -> 0.034759849 | AE16: =MAX(0.005,AE15*0.925) -> 0.0240037 | AF16: =MIN(0.05,AF15*1.02) -> 0.023585025 | AG16: =MAX(0.3,AG15*0.99) -> 0.3619035 | AH16: =1-SUM(AD16:AG16) -> 0.55574792
A17: 17 | B17: 0.12981753 | C17: 0.012278362 | D17: 0 | E17: 0 | F17: 0 | G17: 0 | H17: =AD18/AD17*U17 -> 0.9675 | I17: =V17/V16 -> 0.9 | J17: =AE18/AE17*U17 -> 0.994375 | K17: 1 | L17: =AF18/AF17*U17 -> 1.0965 | M17: =(X17/X16) -> 1.0965 | N17: =AG18/AG17*U17 -> 1.06425 | O17: =(Y17/Y16) -> 0.99 | P17: =AH18/AH17*U17 -> 1.0900442 | Q17: =Z17/Z16 -> 1.0166146 | R17: =LN(S17) -> -0.4230038 | S17: =MAX(0.5,S16*(1.05-0.01*($A17-$A$2))) -> 0.65507614 | T17: =T16*1.075 -> 3.5682603 | U17: =T17/T16 -> 1.075 | V17: =MAX(0.001,V16*0.9) -> 0.013435268 | W17: =W16 -> 0.000915 | X17: =L17*X16 -> 0.00058938651 | Y17: =N17/U17*Y16 -> 0.028980324 | Z17: =AA17-SUM(V17:Y17) -> 0.10608002 | AA17: =AA16 -> 0.15 | AB17: =(0.002+0.00025*A17)*T17*5/S17 -> 0.17022164 | AC17: =R17*0.5 -> -0.2115019 | AD17: =MAX(0.01,AD16*0.9) -> 0.031283864 | AE17: =MAX(0.005,AE16*0.925) -> 0.022203422 | AF17: =MIN(0.05,AF16*1.02) -> 0.024056725 | AG17: =MAX(0.3,AG16*0.99) -> 0.35828447 | AH17: =1-SUM(AD17:AG17) -> 0.56417152
A18: 18 | B18: 0.13113755 | C18: 0.015745191 | D18: 0 | E18: 0 | F18: 0 | G18: 0 | H18: =AD19/AD18*U18 -> 0.9675 | I18: =V18/V17 -> 0.9 | J18: =AE19/AE18*U18 -> 0.994375 | K18: 1 | L18: =AF19/AF18*U18 -> 1.0965 | M18: =(X18/X17) -> 1.0965 | N18: =AG19/AG18*U18 -> 1.06425 | O18: =(Y18/Y17) -> 0.99 | P18: =AH19/AH18*U18 -> 1.0889286 | Q18: =Z18/Z17 -> 1.014861 | R18: =LN(S18) -> -0.53953762 | S18: =MAX(0.5,S17*(1.05-0.01*($A18-$A$2))) -> 0.58301777 | T18: =T17*1.075 -> 3.8358799 | U18: =T18/T17 -> 1.075 | V18: =MAX(0.001,V17*0.9) -> 0.012091741 | W18: =W17 -> 0.000915 | X18: =L18*X17 -> 0.00064626231 | Y18: =N18/U18*Y17 -> 0.028690521 | Z18: =AA18-SUM(V18:Y18) -> 0.10765648 | AA18: =AA17 -> 0.15 | AB18: =(0.002+0.00025*A18)*T18*5/S18 -> 0.21382898 | AC18: =R18*0.5 -> -0.26976881 | AD18: =MAX(0.01,AD17*0.9) -> 0.028155478 | AE18: =MAX(0.005,AE17*0.925) -> 0.020538166 | AF18: =MIN(0.05,AF17*1.02) -> 0.02453786 | AG18: =MAX(0.3,AG17*0.99) -> 0.35470162 | AH18: =1-SUM(AD18:AG18) -> 0.57206687
... A24: 24 | B24: 0.12680298 | C24: 0.06420735 | D24: 0 | E24: 0 | F24: 0 | G24: 0 | H24: =AD25/AD24*U24 -> 0.9675 | I24: =V24/V23 -> 0.9 | J24: =AE25/AE24*U24 -> 0.994375 | K24: 1 | L24: =AF25/AF24*U24 -> 1.0965 | M24: =(X24/X23) -> 1.0965 | N24: =AG25/AG24*U24 -> 1.06425 | O24: =(Y24/Y23) -> 0.99 | P24: =AH25/AH24*U24 -> 1.0842394 | Q24: =Z24/Z23 -> 1.0078144 | R24: =LN(S24) -> -0.69314718 | S24: =MAX(0.5,S23*(1.05-0.01*($A24-$A$2))) -> 0.5 | T24: =T23*1.075 -> 5.9199192 | U24: =T24/T23 -> 1.075 | V24: =MAX(0.001,V23*0.9) -> 0.0064260471 | W24: =W23 -> 0.000915 | X24: =L24*X23 -> 0.0011232092 | Y24: =N24/U24*Y23 -> 0.027011556 | Z24: =AA24-SUM(V24:Y24) -> 0.11452419 | AA24: =AA23 -> 0.15 | AB24: =(0.002+0.00025*A24)*T24*5/S24 -> 0.47359354 | AC24: =R24*0.5 -> -0.34657359 | AD24: =MAX(0.01,AD23*0.9) -> 0.014962975 | AE24: =MAX(0.005,AE23*0.925) -> 0.012865067 | AF24: =MIN(0.05,AF23*1.02) -> 0.027633616 | AG24: =MAX(0.3,AG23*0.99) -> 0.33394454 | AH24: =1-SUM(AD24:AG24) -> 0.61059381
A25: 25 | B25: 0.12386679 | C25: 0.0756581 | D25: 0 | E25: 0 | F25: 0 | G25: 0 | H25: =H24 -> 0.9675 | I25: =0.9*(I24-1)+1 -> 0.91 | J25: =J24 -> 0.994375 | K25: 1 | L25: =L24 -> 1.0965 | M25: =0.9*(M24-1)+1 -> 1.08685 | N25: =N24 -> 1.06425 | O25: =0.9*(O24-1)+1 -> 0.991 | P25: =P24 -> 1.0842394 | Q25: =0.9*(Q24-1)+1 -> 1.007033 | R25: =LN(S25) -> -0.69314718 | S25: =MAX(0.5,S24*(1.05-0.01*($A25-$A$2))) -> 0.5 | T25: =T24*1.075 -> 6.3639132 | U25: =T25/T24 -> 1.075 | V25: =MAX(0.001,V24*0.9) -> 0.0057834424 | W25: =W24 -> 0.000915 | X25: =L25*X24 -> 0.0012315989 | Y25: =N25/U25*Y24 -> 0.02674144 | Z25: =AA25-SUM(V25:Y25) -> 0.11532852 | AA25: =AA24 -> 0.15 | AB25: =(0.002+0.00025*A25)*T25*5/S25 -> 0.52502284 | AC25: =R25*0.5 -> -0.34657359 | AD25: =MAX(0.01,AD24*0.9) -> 0.013466678 | AE25: =MAX(0.005,AE24*0.925) -> 0.011900187 | AF25: =MIN(0.05,AF24*1.02) -> 0.028186288 | AG25: =MAX(0.3,AG24*0.99) -> 0.33060509 | AH25: =1-SUM(AD25:AG25) -> 0.61584176

Sheet NZ
A1: Time | B1: exo_LF_1 | C1: exo_NLF_1 | D1: exo_NX_1 | E1: exo_B_1 | F1: exo_NXL_1 | G1: exo_BL_1 | H1: exo_D_3_1 | I1: exo_E_1 | J1: exo_CapTrade_1 | K1: exo_tauS_1 | L1: E_1
A2: 2 | B2: 0 | C2: 0 | D2: 0 | E2: 0 | F2: 0 | G2: 0 | H2: 0 | I2: =LN(L2) -> 0.048790164 | J2: 1 | K2: 0 | L2: 1.05
A3: 3 | B3: 0.013280752 | C3: 0.0021978191 | D3: 0 | E3: 0 | F3: 0 | G3: 0 | H3: 0 | I3: =LN(L3) -> 0.062693069 | J3: 1 | K3: 0 | L3: =Baseline!S3*0.975 -> 1.0647
A4: 4 | B4: 0.026327978 | C4: 0.0044313875 | D4: 0 | E4: 0 | F4: 0 | G4: 0 | H4: 0 | I4: =LN(L4) -> 0.092251872 | J4: 1 | K4: 0 | L4: =Baseline!S4*0.975 -> 1.096641
A5: 5 | B5: 0.039030698 | C5: 0.0065627985 | D5: 0 | E5: 0 | F5: 0 | G5: 0 | H5: 0 | I5: =LN(L5) -> 0.1120545 | J5: 1 | K5: 0 | L5: =Baseline!S5*0.975 -> 1.1185738
A6: 6 | B6: 0.051256342 | C6: 0.0084316845 | D6: 0 | E6: 0 | F6: 0 | G6: 0 | H6: 0 | I6: =LN(L6) -> 0.12200483 | J6: 1 | K6: 0 | L6: =Baseline!S6*0.975 -> 1.1297596
A7: 7 | B7: 0.062916135 | C7: 0.0099206127 | D7: 0 | E7: 0 | F7: 0 | G7: 0 | H7: 0 | I7: =LN(L7) -> 0.12200483 | J7: 1 | K7: 0 | L7: =Baseline!S7*0.975 -> 1.1297596
A8: 8 | B8: 0.073956933 | C8: 0.010977036 | D8: 0 | E8: 0 | F8: 0 | G8: 0 | H8: 0 | I8: =LN(L8) -> 0.11195449 | J8: 1 | K8: 0 | L8: =Baseline!S8*0.975 -> 1.118462
A9: 9 | B9: 0.082436154 | C9: 0.0097791301 | D9: 0 | E9: 0 | F9: 0 | G9: 0 | H9: 0 | I9: =LN(L9) -> 0.091751787 | J9: 1 | K9: 0 | L9: =Baseline!S9*0.975 -> 1.0960927
A10: 10 | B10: 0.090746583 | C10: 0.008871351 | D10: 0 | E10: 0 | F10: 0 | G10: 0 | H10: 0 | I10: =LN(L10) -> 0.050983209 | J10: 1 | K10: 0 | L10: =Baseline!S10*0.965 -> 1.0523052
A11: 11 | B11: 0.098853018 | C11: 0.0083714865 | D11: 0 | E11: 0 | F11: 0 | G11: 0 | H11: 0 | I11: =LN(L11) -> -0.0055049018 | J11: 1 | K11: 0 | L11: =Baseline!S11*0.95 -> 0.99451022
A12: 12 | B12: 0.10672064 | C12: 0.0083992858 | D12: 0 | E12: 0 | F12: 0 | G12: 0 | H12: 0 | I12: =LN(L12) -> -0.056798196 | J12: 1 | K12: 0 | L12: =Baseline!S12*0.95 -> 0.94478471
A13: 13 | B13: 0.11212457 | C13: 0.0069098571 | D13: 0 | E13: 0 | F13: 0 | G13: 0 | H13: 0 | I13: =LN(L13) -> -0.1186736 | J13: 1 | K13: 0 | L13: =Baseline!S13*0.95 -> 0.88809763
A14: 14 | B14: 0.11720618 | C14: 0.006321377 | D14: 0 | E14: 0 | F14: 0 | G14: 0 | H14: 0 | I14: =LN(L14) -> -0.19124429 | J14: 1 | K14: 0 | L14: =Baseline!S14*0.95 -> 0.82593079
A15: 15 | B15: 0.12189565 | C15: 0.006865972 | D15: 0 | E15: 0 | F15: 0 | G15: 0 | H15: 0 | I15: =LN(L15) -> -0.2746259 | J15: 1 | K15: 0 | L15: =Baseline!S15*0.95 -> 0.75985633
A16: 16 | B16: 0.12612296 | C16: 0.0087754084 | D16: 0 | E16: 0 | F16: 0 | G16: 0 | H16: 0 | I16: =LN(L16) -> -0.36893658 | J16: 1 | K16: 0 | L16: =Baseline!S16*0.95 -> 0.69146926
A17: 17 | B17: 0.12981753 | C17: 0.012278362 | D17: 0 | E17: 0 | F17: 0 | G17: 0 | H17: 0 | I17: =LN(L17) -> -0.4742971 | J17: 1 | K17: 0 | L17: =Baseline!S17*0.95 -> 0.62232234
A18: 18 | B18: 0.13113755 | C18: 0.015745191 | D18: 0 | E18: 0 | F18: 0 | G18: 0 | H18: 0 | I18: =LN(L18) -> -0.65152175 | J18: 1 | K18: 0 | L18: =MIN(Baseline!S18,MAX(0.11,0.975^($A18-$A$11)*L17)) -> 0.52125196
A19: 19 | B19: 0.13190974 | C19: 0.020882947 | D19: 0 | E19: 0 | F19: 0 | G19: 0 | H19: 0 | I19: =LN(L19) -> -0.85406422 | J19: 1 | K19: 0 | L19: =MIN(Baseline!S19,MAX(0.11,0.975^($A19-$A$11)*L18)) -> 0.42568135
A20: 20 | B20: 0.13217878 | C20: 0.027533148 | D20: 0 | E20: 0 | F20: 0 | G20: 0 | H20: 0 | I20: =LN(L20) -> -1.0819245 | J20: 1 | K20: 0 | L20: =MIN(Baseline!S20,MAX(0.11,0.975^($A20-$A$11)*L19)) -> 0.33894261
A21: 21 | B21: 0.13198781 | C21: 0.035536087 | D21: 0 | E21: 0 | F21: 0 | G21: 0 | H21: 0 | I21: =LN(L21) -> -1.3351026 | J21: =1+(J20-1)*0.99 -> 1 | K21: 0 | L21: =MIN(Baseline!S21,MAX(0.11,0.975^($A21-$A$11)*L20)) -> 0.26313119
A22: 22 | B22: 0.13137862 | C22: 0.04473281 | D22: 0 | E22: 0 | F22: 0 | G22: 0 | H22: 0 | I22: =LN(L22) -> -1.6135985 | J22: =1+(J21-1)*0.99 -> 1 | K22: 0 | L22: =MIN(Baseline!S22,MAX(0.11,0.975^($A22-$A$11)*L21)) -> 0.19916962
A23: 23 | B23: 0.1292951 | C23: 0.05391862 | D23: 0 | E23: 0 | F23: 0 | G23: 0 | H23: 0 | I23: =LN(L23) -> -1.9174122 | J23: =1+(J22-1)*0.99 -> 1 | K23: 0 | L23: =MIN(Baseline!S23,MAX(0.11,0.975^($A23-$A$11)*L22)) -> 0.14698685
A24: 24 | B24: 0.12680298 | C24: 0.06420735 | D24: 0 | E24: 0 | F24: 0 | G24: 0 | H24: 0 | I24: =LN(L24) -> -2.2072749 | J24: =1+(J23-1)*0.99 -> 1 | K24: 0 | L24: =MIN(Baseline!S24,MAX(0.11,0.975^($A24-$A$11)*L23)) -> 0.11
A25: 25 | B25: 0.12386679 | C25: 0.0756581 | D25: 0 | E25: 0 | F25: 0 | G25: 0 | H25: 0 | I25: =LN(L25) -> -2.2072749 | J25: =1+(J24-1)*0.99 -> 1 | K25: 0 | L25: =MIN(Baseline!S25,MAX(0.11,0.975^($A25-$A$11)*L24)) -> 0.11

Sheet NZ_constEE
A1: Time | B1: exo_LF_1 | C1: exo_NLF_1 | D1: exo_NX_1 | E1: exo_B_1 | F1: exo_NXL_1 | G1: exo_BL_1 | H1: exo_D_3_1 | I1: exo_E_1 | J1: exo_CapTrade_1 | K1: exo_tauS_1 | L1: E_1 | M1: exo_EE_1
A2: 2 | B2: 0 | C2: 0 | D2: 0 | E2: 0 | F2: 0 | G2: 0 | H2: 0 | I2: =LN(L2) -> 0.048790164 | J2: 1 | K2: 1 | L2: =NZ!L2 -> 1.05 | M2: 0
A3: 3 | B3: 0.013280752 | C3: 0.0021978191 | D3: 0 | E3: 0 | F3: 0 | G3: 0 | H3: 0 | I3: =LN(L3) -> 0.062693069 | J3: 1 | K3: 1 | L3: =NZ!L3 -> 1.0647 | M3: 0
A4: 4 | B4: 0.026327978 | C4: 0.0044313875 | D4: 0 | E4: 0 | F4: 0 | G4: 0 | H4: 0 | I4: =LN(L4) -> 0.092251872 | J4: 1 | K4: 1 | L4: =NZ!L4 -> 1.096641 | M4: 0
A5: 5 | B5: 0.039030698 | C5: 0.0065627985 | D5: 0 | E5: 0 | F5: 0 | G5: 0 | H5: 0 | I5: =LN(L5) -> 0.1120545 | J5: 1 | K5: 1 | L5: =NZ!L5 -> 1.1185738 | M5: 0
A6: 6 | B6: 0.051256342 | C6: 0.0084316845 | D6: 0 | E6: 0 | F6: 0 | G6: 0 | H6: 0 | I6: =LN(L6) -> 0.12200483 | J6: 1 | K6: 1 | L6: =NZ!L6 -> 1.1297596 | M6: 0
A7: 7 | B7: 0.062916135 | C7: 0.0099206127 | D7: 0 | E7: 0 | F7: 0 | G7: 0 | H7: 0 | I7: =LN(L7) -> 0.12200483 | J7: 1 | K7: 1 | L7: =NZ!L7 -> 1.1297596 | M7: 0
A8: 8 | B8: 0.073956933 | C8: 0.010977036 | D8: 0 | E8: 0 | F8: 0 | G8: 0 | H8: 0 | I8: =LN(L8) -> 0.11195449 | J8: 1 | K8: 1 | L8: =NZ!L8 -> 1.118462 | M8: 0
A9: 9 | B9: 0.082436154 | C9: 0.0097791301 | D9: 0 | E9: 0 | F9: 0 | G9: 0 | H9: 0 | I9: =LN(L9) -> 0.091751787 | J9: 1 | K9: 1 | L9: =NZ!L9 -> 1.0960927 | M9: 0
A10: 10 | B10: 0.090746583 | C10: 0.008871351 | D10: 0 | E10: 0 | F10: 0 | G10: 0 | H10: 0 | I10: =LN(L10) -> 0.050983209 | J10: 1 | K10: 1 | L10: =NZ!L10 -> 1.0523052 | M10: 0
A11: 11 | B11: 0.098853018 | C11: 0.0083714865 | D11: 0 | E11: 0 | F11: 0 | G11: 0 | H11: 0 | I11: =LN(L11) -> -0.0055049018 | J11: 1 | K11: 1 | L11: =NZ!L11 -> 0.99451022 | M11: 0
A12: 12 | B12: 0.10672064 | C12: 0.0083992858 | D12: 0 | E12: 0 | F12: 0 | G12: 0 | H12: 0 | I12: =LN(L12) -> -0.056798196 | J12: 1 | K12: 1 | L12: =NZ!L12 -> 0.94478471 | M12: 0
A13: 13 | B13: 0.11212457 | C13: 0.0069098571 | D13: 0 | E13: 0 | F13: 0 | G13: 0 | H13: 0 | I13: =LN(L13) -> -0.1186736 | J13: 1 | K13: 1 | L13: =NZ!L13 -> 0.88809763 | M13: 0
... A20: 20 | B20: 0.13217878 | C20: 0.027533148 | D20: 0 | E20: 0 | F20: 0 | G20: 0 | H20: 0 | I20: =LN(L20) -> -1.0819245 | J20: 1 | K20: 1 | L20: =NZ!L20 -> 0.33894261 | M20: 0
A21: 21 | B21: 0.13198781 | C21: 0.035536087 | D21: 0 | E21: 0 | F21: 0 | G21: 0 | H21: 0 | I21: =LN(L21) -> -1.3351026 | J21: =1+(J20-1)*0.99 -> 1 | K21: 1 | L21: =NZ!L21 -> 0.26313119 | M21: 0
A22: 22 | B22: 0.13137862 | C22: 0.04473281 | D22: 0 | E22: 0 | F22: 0 | G22: 0 | H22: 0 | I22: =LN(L22) -> -1.6135985 | J22: =1+(J21-1)*0.99 -> 1 | K22: 1 | L22: =NZ!L22 -> 0.19916962 | M22: 0
A23: 23 | B23: 0.1292951 | C23: 0.05391862 | D23: 0 | E23: 0 | F23: 0 | G23: 0 | H23: 0 | I23: =LN(L23) -> -1.9174122 | J23: =1+(J22-1)*0.99 -> 1 | K23: 1 | L23: =NZ!L23 -> 0.14698685 | M23: 0
A24: 24 | B24: 0.12680298 | C24: 0.06420735 | D24: 0 | E24: 0 | F24: 0 | G24: 0 | H24: 0 | I24: =LN(L24) -> -2.2072749 | J24: =1+(J23-1)*0.99 -> 1 | K24: 1 | L24: =NZ!L24 -> 0.11 | M24: 0
A25: 25 | B25: 0.12386679 | C25: 0.0756581 | D25: 0 | E25: 0 | F25: 0 | G25: 0 | H25: 0 | I25: =LN(L25) -> -2.2072749 | J25: =1+(J24-1)*0.99 -> 1 | K25: 1 | L25: =NZ!L25 -> 0.11 | M25: 0

Sheet NZ_constInt
A1: Time | B1: exo_LF_1 | C1: exo_NLF_1 | D1: exo_NX_1 | E1: exo_B_1 | F1: exo_NXL_1 | G1: exo_BL_1 | H1: exo_D_3_1 | I1: exo_E_1 | J1: exo_CapTrade_1 | K1: exo_tauS_1 | L1: exo_kappaE_2_1 | M1: E_1
A2: 2 | B2: 0 | C2: 0 | D2: 0 | E2: 0 | F2: 0 | G2: 0 | H2: 0 | I2: =LN(M2) -> 0.048790164 | J2: 1 | K2: 1 | L2: 0 | M2: =NZ!L2 -> 1.05
A3: 3 | B3: 0.013280752 | C3: 0.0021978191 | D3: 0 | E3: 0 | F3: 0 | G3: 0 | H3: 0 | I3: =LN(M3) -> 0.062693069 | J3: 1 | K3: 1 | L3: 0 | M3: =NZ!L3 -> 1.0647
A4: 4 | B4: 0.026327978 | C4: 0.0044313875 | D4: 0 | E4: 0 | F4: 0 | G4: 0 | H4: 0 | I4: =LN(M4) -> 0.092251872 | J4: 1 | K4: 1 | L4: 0 | M4: =NZ!L4 -> 1.096641
A5: 5 | B5: 0.039030698 | C5: 0.0065627985 | D5: 0 | E5: 0 | F5: 0 | G5: 0 | H5: 0 | I5: =LN(M5) -> 0.1120545 | J5: 1 | K5: 1 | L5: 0 | M5: =NZ!L5 -> 1.1185738
A6: 6 | B6: 0.051256342 | C6: 0.0084316845 | D6: 0 | E6: 0 | F6: 0 | G6: 0 | H6: 0 | I6: =LN(M6) -> 0.12200483 | J6: 1 | K6: 1 | L6: 0 | M6: =NZ!L6 -> 1.1297596
A7: 7 | B7: 0.062916135 | C7: 0.0099206127 | D7: 0 | E7: 0 | F7: 0 | G7: 0 | H7: 0 | I7: =LN(M7) -> 0.12200483 | J7: 1 | K7: 1 | L7: 0 | M7: =NZ!L7 -> 1.1297596
A8: 8 | B8: 0.073956933 | C8: 0.010977036 | D8: 0 | E8: 0 | F8: 0 | G8: 0 | H8: 0 | I8: =LN(M8) -> 0.11195449 | J8: 1 | K8: 1 | L8: 0 | M8: =NZ!L8 -> 1.118462
A9: 9 | B9: 0.082436154 | C9: 0.0097791301 | D9: 0 | E9: 0 | F9: 0 | G9: 0 | H9: 0 | I9: =LN(M9) -> 0.091751787 | J9: 1 | K9: 1 | L9: 0 | M9: =NZ!L9 -> 1.0960927
A10: 10 | B10: 0.090746583 | C10: 0.008871351 | D10: 0 | E10: 0 | F10: 0 | G10: 0 | H10: 0 | I10: =LN(M10) -> 0.050983209 | J10: 1 | K10: 1 | L10: 0 | M10: =NZ!L10 -> 1.0523052
A11: 11 | B11: 0.098853018 | C11: 0.0083714865 | D11: 0 | E11: 0 | F11: 0 | G11: 0 | H11: 0 | I11: =LN(M11) -> -0.0055049018 | J11: 1 | K11: 1 | L11: 0 | M11: =NZ!L11 -> 0.99451022
A12: 12 | B12: 0.10672064 | C12: 0.0083992858 | D12: 0 | E12: 0 | F12: 0 | G12: 0 | H12: 0 | I12: =LN(M12) -> -0.056798196 | J12: 1 | K12: 1 | L12: 0 | M12: =NZ!L12 -> 0.94478471
A13: 13 | B13: 0.11212457 | C13: 0.0069098571 | D13: 0 | E13: 0 | F13: 0 | G13: 0 | H13: 0 | I13: =LN(M13) -> -0.1186736 | J13: 1 | K13: 1 | L13: 0 | M13: =NZ!L13 -> 0.88809763
... A20: 20 | B20: 0.13217878 | C20: 0.027533148 | D20: 0 | E20: 0 | F20: 0 | G20: 0 | H20: 0 | I20: =LN(M20) -> -1.0819245 | J20: 1 | K20: 1 | L20: 0 | M20: =NZ!L20 -> 0.33894261
A21: 21 | B21: 0.13198781 | C21: 0.035536087 | D21: 0 | E21: 0 | F21: 0 | G21: 0 | H21: 0 | I21: =LN(M21) -> -1.3351026 | J21: =1+(J20-1)*0.99 -> 1 | K21: 1 | L21: 0 | M21: =NZ!L21 -> 0.26313119
A22: 22 | B22: 0.13137862 | C22: 0.04473281 | D22: 0 | E22: 0 | F22: 0 | G22: 0 | H22: 0 | I22: =LN(M22) -> -1.6135985 | J22: =1+(J21-1)*0.99 -> 1 | K22: 1 | L22: 0 | M22: =NZ!L22 -> 0.19916962
A23: 23 | B23: 0.1292951 | C23: 0.05391862 | D23: 0 | E23: 0 | F23: 0 | G23: 0 | H23: 0 | I23: =LN(M23) -> -1.9174122 | J23: =1+(J22-1)*0.99 -> 1 | K23: 1 | L23: 0 | M23: =NZ!L23 -> 0.14698685
A24: 24 | B24: 0.12680298 | C24: 0.06420735 | D24: 0 | E24: 0 | F24: 0 | G24: 0 | H24: 0 | I24: =LN(M24) -> -2.2072749 | J24: =1+(J23-1)*0.99 -> 1 | K24: 1 | L24: 0 | M24: =NZ!L24 -> 0.11
A25: 25 | B25: 0.12386679 | C25: 0.0756581 | D25: 0 | E25: 0 | F25: 0 | G25: 0 | H25: 0 | I25: =LN(M25) -> -2.2072749 | J25: =1+(J24-1)*0.99 -> 1 | K25: 1 | L25: 0 | M25: =NZ!L25 -> 0.11

Sheet NZ_constEEInt
A1: Time | B1: exo_LF_1 | C1: exo_NLF_1 | D1: exo_NX_1 | E1: exo_B_1 | F1: exo_NXL_1 | G1: exo_BL_1 | H1: exo_D_3_1 | I1: exo_E_1 | J1: exo_CapTrade_1 | K1: exo_tauS_1 | L1: E_1 | M1: exo_EE_1 | N1: exo_kappaE_2_1
A2: 2 | B2: 0 | C2: 0 | D2: 0 | E2: 0 | F2: 0 | G2: 0 | H2: 0 | I2: =LN(L2) -> 0.048790164 | J2: 1 | K2: 1 | L2: =NZ!L2 -> 1.05 | M2: 0 | N2: =NZ!M2 -> 0
A3: 3 | B3: 0.013280752 | C3: 0.0021978191 | D3: 0 | E3: 0 | F3: 0 | G3: 0 | H3: 0 | I3: =LN(L3) -> 0.062693069 | J3: 1 | K3: 1 | L3: =NZ!L3 -> 1.0647 | M3: 0 | N3: =NZ!M3 -> 0
A4: 4 | B4: 0.026327978 | C4: 0.0044313875 | D4: 0 | E4: 0 | F4: 0 | G4: 0 | H4: 0 | I4: =LN(L4) -> 0.092251872 | J4: 1 | K4: 1 | L4: =NZ!L4 -> 1.096641 | M4: 0 | N4: =NZ!M4 -> 0
A5: 5 | B5: 0.039030698 | C5: 0.0065627985 | D5: 0 | E5: 0 | F5: 0 | G5: 0 | H5: 0 | I5: =LN(L5) -> 0.1120545 | J5: 1 | K5: 1 | L5: =NZ!L5 -> 1.1185738 | M5: 0 | N5: =NZ!M5 -> 0
A6: 6 | B6: 0.051256342 | C6: 0.0084316845 | D6: 0 | E6: 0 | F6: 0 | G6: 0 | H6: 0 | I6: =LN(L6) -> 0.12200483 | J6: 1 | K6: 1 | L6: =NZ!L6 -> 1.1297596 | M6: 0 | N6: =NZ!M6 -> 0
A7: 7 | B7: 0.062916135 | C7: 0.0099206127 | D7: 0 | E7: 0 | F7: 0 | G7: 0 | H7: 0 | I7: =LN(L7) -> 0.12200483 | J7: 1 | K7: 1 | L7: =NZ!L7 -> 1.1297596 | M7: 0 | N7: =NZ!M7 -> 0
A8: 8 | B8: 0.073956933 | C8: 0.010977036 | D8: 0 | E8: 0 | F8: 0 | G8: 0 | H8: 0 | I8: =LN(L8) -> 0.11195449 | J8: 1 | K8: 1 | L8: =NZ!L8 -> 1.118462 | M8: 0 | N8: =NZ!M8 -> 0
A9: 9 | B9: 0.082436154 | C9: 0.0097791301 | D9: 0 | E9: 0 | F9: 0 | G9: 0 | H9: 0 | I9: =LN(L9) -> 0.091751787 | J9: 1 | K9: 1 | L9: =NZ!L9 -> 1.0960927 | M9: 0 | N9: =NZ!M9 -> 0
A10: 10 | B10: 0.090746583 | C10: 0.008871351 | D10: 0 | E10: 0 | F10: 0 | G10: 0 | H10: 0 | I10: =LN(L10) -> 0.050983209 | J10: 1 | K10: 1 | L10: =NZ!L10 -> 1.0523052 | M10: 0 | N10: =NZ!M10 -> 0
A11: 11 | B11: 0.098853018 | C11: 0.0083714865 | D11: 0 | E11: 0 | F11: 0 | G11: 0 | H11: 0 | I11: =LN(L11) -> -0.0055049018 | J11: 1 | K11: 1 | L11: =NZ!L11 -> 0.99451022 | M11: 0 | N11: =NZ!M11 -> 0
A12: 12 | B12: 0.10672064 | C12: 0.0083992858 | D12: 0 | E12: 0 | F12: 0 | G12: 0 | H12: 0 | I12: =LN(L12) -> -0.056798196 | J12: 1 | K12: 1 | L12: =NZ!L12 -> 0.94478471 | M12: 0 | N12: =NZ!M12 -> 0
A13: 13 | B13: 0.11212457 | C13: 0.0069098571 | D13: 0 | E13: 0 | F13: 0 | G13: 0 | H13: 0 | I13: =LN(L13) -> -0.1186736 | J13: 1 | K13: 1 | L13: =NZ!L13 -> 0.88809763 | M13: 0 | N13: =NZ!M13 -> 0
... A20: 20 | B20: 0.13217878 | C20: 0.027533148 | D20: 0 | E20: 0 | F20: 0 | G20: 0 | H20: 0 | I20: =LN(L20) -> -1.0819245 | J20: 1 | K20: 1 | L20: =NZ!L20 -> 0.33894261 | M20: 0 | N20: =NZ!M20 -> 0
A21: 21 | B21: 0.13198781 | C21: 0.035536087 | D21: 0 | E21: 0 | F21: 0 | G21: 0 | H21: 0 | I21: =LN(L21) -> -1.3351026 | J21: =1+(J20-1)*0.99 -> 1 | K21: 1 | L21: =NZ!L21 -> 0.26313119 | M21: 0 | N21: =NZ!M21 -> 0
A22: 22 | B22: 0.13137862 | C22: 0.04473281 | D22: 0 | E22: 0 | F22: 0 | G22: 0 | H22: 0 | I22: =LN(L22) -> -1.6135985 | J22: =1+(J21-1)*0.99 -> 1 | K22: 1 | L22: =NZ!L22 -> 0.19916962 | M22: 0 | N22: =NZ!M22 -> 0
A23: 23 | B23: 0.1292951 | C23: 0.05391862 | D23: 0 | E23: 0 | F23: 0 | G23: 0 | H23: 0 | I23: =LN(L23) -> -1.9174122 | J23: =1+(J22-1)*0.99 -> 1 | K23: 1 | L23: =NZ!L23 -> 0.14698685 | M23: 0 | N23: =NZ!M23 -> 0
A24: 24 | B24: 0.12680298 | C24: 0.06420735 | D24: 0 | E24: 0 | F24: 0 | G24: 0 | H24: 0 | I24: =LN(L24) -> -2.2072749 | J24: =1+(J23-1)*0.99 -> 1 | K24: 1 | L24: =NZ!L24 -> 0.11 | M24: 0 | N24: =NZ!M24 -> 0
A25: 25 | B25: 0.12386679 | C25: 0.0756581 | D25: 0 | E25: 0 | F25: 0 | G25: 0 | H25: 0 | I25: =LN(L25) -> -2.2072749 | J25: =1+(J24-1)*0.99 -> 1 | K25: 1 | L25: =NZ!L25 -> 0.11 | M25: 0 | N25: =NZ!M25 -> 0
